Workbook

Sheet Daily Log
A1: Date | B1: Day of Week | C1: Breakfast (kcal) | D1: Lunch (kcal) | E1: Dinner (kcal) | F1: Snacks (kcal) | G1: Calories Eaten (ATE) | H1: Exercise Calories | I1: Total Calories Burned | J1: Net Calories (Eaten-Burned) | K1: Weight (kg) | L1: Vacay Day? | M1: Include in Averages?
A2: 46181 | B2: =TEXT(A2,"ddd") -> Mon | C2: 290 | D2: 300 | E2: 480 | F2: 1070 | G2: 2140 | H2: 250 | I2: 1828 | J2: =IF(OR(G2="",I2=""),"",G2-I2) -> 312 | K2: 71.3 | L2: No | M2: =IF(AND(L2="No",I2<>""),1,0) -> 1
A3: 46182 | B3: =TEXT(A3,"ddd") -> Tue | C3: 320 | D3: 650 | E3: 380 | F3: 330 | G3: 1680 | H3: 200 | I3: 1010 | J3: =IF(OR(G3="",I3=""),"",G3-I3) -> 670 | L3: No | M3: =IF(AND(L3="No",I3<>""),1,0) -> 1
A4: 46183 | B4: =TEXT(A4,"ddd") -> Wed | C4: 230 | D4: 750 | E4: 760 | F4: 270 | G4: 2010 | H4: 300 | I4: 1802 | J4: =IF(OR(G4="",I4=""),"",G4-I4) -> 208 | L4: No | M4: =IF(AND(L4="No",I4<>""),1,0) -> 1
A5: 46184 | B5: =TEXT(A5,"ddd") -> Thu | C5: 240 | D5: 490 | E5: 780 | F5: 0 | G5: 1510 | H5: 325 | I5: 1420 | J5: =IF(OR(G5="",I5=""),"",G5-I5) -> 90 | L5: No | M5: =IF(AND(L5="No",I5<>""),1,0) -> 1
A6: 46185 | B6: =TEXT(A6,"ddd") -> Fri | C6: 370 | D6: 250 | E6: 770 | F6: 360 | G6: 1750 | H6: 150 | I6: 1125 | J6: =IF(OR(G6="",I6=""),"",G6-I6) -> 625 | L6: No | M6: =IF(AND(L6="No",I6<>""),1,0) -> 1
A7: 46186 | B7: =TEXT(A7,"ddd") -> Sat | C7: 230 | D7: 750 | E7: 710 | F7: 200 | G7: 1890 | H7: 275 | I7: 1803 | J7: =IF(OR(G7="",I7=""),"",G7-I7) -> 87 | L7: No | M7: =IF(AND(L7="No",I7<>""),1,0) -> 1
A8: 46187 | B8: =TEXT(A8,"ddd") -> Sun | C8: 280 | D8: 800 | E8: 540 | F8: 180 | G8: 1800 | H8: 250 | I8: 1771 | J8: =IF(OR(G8="",I8=""),"",G8-I8) -> 29 | L8: No | M8: =IF(AND(L8="No",I8<>""),1,0) -> 1
A9: 46188 | B9: =TEXT(A9,"ddd") -> Mon | C9: 600 | D9: 500 | E9: 810 | F9: 990 | G9: 2410 | I9: 1705 | J9: =IF(OR(G9="",I9=""),"",G9-I9) -> 705 | K9: 70.9 | L9: No | M9: =IF(AND(L9="No",I9<>""),1,0) -> 1
A10: 46189 | B10: =TEXT(A10,"ddd") -> Tue | C10: 230 | D10: 530 | E10: 510 | F10: 130 | G10: 1400 | I10: 1688 | J10: =IF(OR(G10="",I10=""),"",G10-I10) -> -288 | L10: No | M10: =IF(AND(L10="No",I10<>""),1,0) -> 1
A11: 46190 | B11: =TEXT(A11,"ddd") -> Wed | C11: 340 | D11: 600 | E11: 550 | F11: 385 | G11: 1875 | I11: 1710 | J11: =IF(OR(G11="",I11=""),"",G11-I11) -> 165 | L11: No | M11: =IF(AND(L11="No",I11<>""),1,0) -> 1
A12: 46191 | B12: =TEXT(A12,"ddd") -> Thu | C12: 90 | D12: 450 | E12: 410 | F12: 480 | G12: 1430 | I12: 1510 | J12: =IF(OR(G12="",I12=""),"",G12-I12) -> -80 | L12: No | M12: =IF(AND(L12="No",I12<>""),1,0) -> 1
A13: 46192 | B13: =TEXT(A13,"ddd") -> Fri | C13: 320 | D13: 500 | E13: 300 | F13: 430 | G13: 1550 | I13: 1442 | J13: =IF(OR(G13="",I13=""),"",G13-I13) -> 108 | L13: No | M13: =IF(AND(L13="No",I13<>""),1,0) -> 1
A14: 46193 | B14: =TEXT(A14,"ddd") -> Sat | C14: 450 | D14: 810 | E14: 0 | F14: 140 | G14: 1400 | I14: 1840 | J14: =IF(OR(G14="",I14=""),"",G14-I14) -> -440 | L14: No | M14: =IF(AND(L14="No",I14<>""),1,0) -> 1
A15: 46194 | B15: =TEXT(A15,"ddd") -> Sun | C15: 750 | D15: 250 | E15: 520 | F15: 160 | G15: 1680 | I15: 1830 | J15: =IF(OR(G15="",I15=""),"",G15-I15) -> -150 | L15: No | M15: =IF(AND(L15="No",I15<>""),1,0) -> 1
A16: 46195 | B16: =TEXT(A16,"ddd") -> Mon | C16: 290 | D16: 650 | E16: 350 | F16: 480 | G16: 1970 | I16: 1716 | J16: =IF(OR(G16="",I16=""),"",G16-I16) -> 254 | K16: 70.5 | L16: No | M16: =IF(AND(L16="No",I16<>""),1,0) -> 1
A17: 46196 | B17: =TEXT(A17,"ddd") -> Tue | C17: 420 | D17: 600 | E17: 270 | F17: 300 | G17: 1590 | I17: 1708 | J17: =IF(OR(G17="",I17=""),"",G17-I17) -> -118 | L17: No | M17: =IF(AND(L17="No",I17<>""),1,0) -> 1
A18: 46197 | B18: =TEXT(A18,"ddd") -> Wed | C18: 400 | D18: 320 | E18: 720 | F18: 260 | G18: 1700 | I18: 1618 | J18: =IF(OR(G18="",I18=""),"",G18-I18) -> 82 | L18: No | M18: =IF(AND(L18="No",I18<>""),1,0) -> 1
A19: 46198 | B19: =TEXT(A19,"ddd") -> Thu | C19: 230 | D19: 540 | E19: 840 | F19: 90 | G19: 1700 | I19: 1774 | J19: =IF(OR(G19="",I19=""),"",G19-I19) -> -74 | L19: No | M19: =IF(AND(L19="No",I19<>""),1,0) -> 1
A20: 46199 | B20: =TEXT(A20,"ddd") -> Fri | C20: 380 | D20: 680 | E20: 640 | F20: 780 | G20: 2680 | I20: 1800 | J20: =IF(OR(G20="",I20=""),"",G20-I20) -> 880 | L20: Yes | M20: =IF(AND(L20="No",I20<>""),1,0) -> 0
A21: 46200 | B21: =TEXT(A21,"ddd") -> Sat | C21: 800 | D21: 410 | E21: 700 | F21: 1210 | G21: 3120 | I21: 2085 | J21: =IF(OR(G21="",I21=""),"",G21-I21) -> 1035 | L21: Yes | M21: =IF(AND(L21="No",I21<>""),1,0) -> 0
A22: 46201 | B22: =TEXT(A22,"ddd") -> Sun | C22: 960 | D22: 790 | E22: 700 | F22: 130 | G22: 2530 | I22: 1596 | J22: =IF(OR(G22="",I22=""),"",G22-I22) -> 934 | L22: Yes | M22: =IF(AND(L22="No",I22<>""),1,0) -> 0
A23: 46202 | B23: =TEXT(A23,"ddd") -> Mon | C23: 110 | D23: 650 | E23: 420 | F23: 570 | G23: 1750 | I23: 1666 | J23: =IF(OR(G23="",I23=""),"",G23-I23) -> 84 | K23: 71.6 | L23: No | M23: =IF(AND(L23="No",I23<>""),1,0) -> 1
A24: 46203 | B24: =TEXT(A24,"ddd") -> Tue | C24: 180 | D24: 530 | E24: 650 | F24: 100 | G24: 1540 | I24: 1887 | J24: =IF(OR(G24="",I24=""),"",G24-I24) -> -347 | L24: No | M24: =IF(AND(L24="No",I24<>""),1,0) -> 1
A25: 46204 | B25: =TEXT(A25,"ddd") -> Wed | C25: 430 | D25: 470 | E25: 680 | F25: 240 | G25: 1820 | I25: 1046 | J25: =IF(OR(G25="",I25=""),"",G25-I25) -> 774 | L25: No | M25: =IF(AND(L25="No",I25<>""),1,0) -> 1
A26: 46205 | B26: =TEXT(A26,"ddd") -> Thu | C26: 180 | D26: 520 | E26: 900 | F26: 270 | G26: 1870 | I26: 1795 | J26: =IF(OR(G26="",I26=""),"",G26-I26) -> 75 | L26: No | M26: =IF(AND(L26="No",I26<>""),1,0) -> 1
A27: 46206 | B27: =TEXT(A27,"ddd") -> Fri | C27: 725 | D27: 650 | E27: 650 | F27: 25 | G27: 2050 | I27: 1657 | J27: =IF(OR(G27="",I27=""),"",G27-I27) -> 393 | L27: No | M27: =IF(AND(L27="No",I27<>""),1,0) -> 1
A28: 46207 | B28: =TEXT(A28,"ddd") -> Sat | C28: 400 | D28: 500 | E28: 560 | F28: 580 | G28: 2040 | I28: 1761 | J28: =IF(OR(G28="",I28=""),"",G28-I28) -> 279 | L28: No | M28: =IF(AND(L28="No",I28<>""),1,0) -> 1
A29: 46208 | B29: =TEXT(A29,"ddd") -> Sun | C29: 240 | D29: 510 | E29: 845 | F29: 120 | G29: 1715 | I29: 2099 | J29: =IF(OR(G29="",I29=""),"",G29-I29) -> -384 | L29: No | M29: =IF(AND(L29="No",I29<>""),1,0) -> 1
A30: 46209 | B30: =TEXT(A30,"ddd") -> Mon | C30: 370 | D30: 600 | E30: 430 | F30: 120 | G30: 1520 | I30: 1563 | J30: =IF(OR(G30="",I30=""),"",G30-I30) -> -43 | K30: 70.65 | L30: No | M30: =IF(AND(L30="No",I30<>""),1,0) -> 1
A31: 46210 | B31: =TEXT(A31,"ddd") -> Tue | C31: 300 | D31: 600 | E31: 600 | F31: 620 | G31: 2120 | I31: 1689 | J31: =IF(OR(G31="",I31=""),"",G31-I31) -> 431 | L31: No | M31: =IF(AND(L31="No",I31<>""),1,0) -> 1
A32: 46211 | B32: =TEXT(A32,"ddd") -> Wed | C32: 310 | D32: 410 | E32: 570 | F32: 500 | G32: 1790 | I32: 1839 | J32: =IF(OR(G32="",I32=""),"",G32-I32) -> -49 | L32: No | M32: =IF(AND(L32="No",I32<>""),1,0) -> 1
A33: 46212 | B33: =TEXT(A33,"ddd") -> Thu | C33: 240 | D33: 700 | E33: 350 | F33: 695 | G33: 1965 | I33: 1844 | J33: =IF(OR(G33="",I33=""),"",G33-I33) -> 121 | L33: No | M33: =IF(AND(L33="No",I33<>""),1,0) -> 1
A34: 46213 | B34: =TEXT(A34,"ddd") -> Fri | C34: 330 | D34: 600 | E34: 620 | F34: 60 | G34: 1610 | I34: 1494 | J34: =IF(OR(G34="",I34=""),"",G34-I34) -> 116 | L34: No | M34: =IF(AND(L34="No",I34<>""),1,0) -> 1
A35: 46214 | B35: =TEXT(A35,"ddd") -> Sat | C35: 350 | D35: 450 | E35: 600 | F35: 0 | G35: 1400 | I35: 1585 | J35: =IF(OR(G35="",I35=""),"",G35-I35) -> -185 | L35: No | M35: =IF(AND(L35="No",I35<>""),1,0) -> 1
A36: 46215 | B36: =TEXT(A36,"ddd") -> Sun | C36: 490 | D36: 0 | E36: 850 | F36: 300 | G36: 1640 | I36: 1700 | J36: =IF(OR(G36="",I36=""),"",G36-I36) -> -60 | L36: No | M36: =IF(AND(L36="No",I36<>""),1,0) -> 1
A37: 46216 | B37: =TEXT(A37,"ddd") -> Mon | C37: 390 | D37: 600 | E37: 730 | F37: 650 | G37: 2370 | I37: 1846 | J37: =IF(OR(G37="",I37=""),"",G37-I37) -> 524 | K37: 70.9 | L37: No | M37: =IF(AND(L37="No",I37<>""),1,0) -> 1
A38: 46217 | B38: =TEXT(A38,"ddd") -> Tue | C38: 250 | D38: 500 | E38: 450 | F38: 450 | G38: 1650 | I38: 1645 | J38: =IF(OR(G38="",I38=""),"",G38-I38) -> 5 | L38: No | M38: =IF(AND(L38="No",I38<>""),1,0) -> 1
A39: 46218 | B39: =TEXT(A39,"ddd") -> Wed | C39: 490 | D39: 450 | E39: 600 | F39: 330 | G39: 1870 | I39: 1379 | J39: =IF(OR(G39="",I39=""),"",G39-I39) -> 491 | L39: No | M39: =IF(AND(L39="No",I39<>""),1,0) -> 1
A40: 46219 | B40: =TEXT(A40,"ddd") -> Thu | C40: 560 | D40: 300 | E40: 700 | F40: 290 | G40: 1850 | I40: 1398 | J40: =IF(OR(G40="",I40=""),"",G40-I40) -> 452 | L40: No | M40: =IF(AND(L40="No",I40<>""),1,0) -> 1
...

Sheet Goal Summary
A1: Weight Loss Goal Summary
A3: Height (cm) | B3: 157
A4: Start Date | B4: 46181
A5: Start Weight (kg) | B5: 71.3
A6: Goal Weight (kg) | B6: 62
A7: kcal per kg of body fat | B7: 7700
A9: Latest Logged Weight (kg) | B9: =LOOKUP(2,1/('Daily Log'!$K$2:$K$80<>""),'Daily Log'!$K$2:$K$80) -> 71.2
A10: Latest Weigh-in Date | B10: =LOOKUP(2,1/('Daily Log'!$K$2:$K$80<>""),'Daily Log'!$A$2:$A$80) -> 46258
A12: Weight Still to Lose (kg) | B12: =B9-B6 -> 9.2
A13: Total Weight Lost So Far (kg) | B13: =B5-B9 -> 0.1
A15: Average Daily Calories Eaten (excl. vacay) | B15: =AVERAGEIFS('Daily Log'!$G$2:$G$80,'Daily Log'!$M$2:$M$80,1) -> 1739.7733
A16: Average Daily Calories Burned (excl. vacay) | B16: =AVERAGEIFS('Daily Log'!$I$2:$I$80,'Daily Log'!$M$2:$M$80,1) -> 1724.6933
A17: Average Daily Net Deficit (Burn-Eat, excl. vacay) | B17: =B16-B15 -> -15.08
A19: Estimated Days to Reach Goal (data-driven) | B19: =IF(B17<=0,"No net deficit yet",(B12*B7)/B17) -> No net deficit yet
A20: Estimated Weeks to Reach Goal | B20: =IF(ISNUMBER(B19),B19/7,"-") -> -
A21: Estimated Goal Date | B21: =IF(ISNUMBER(B19),B10+B19,"-") -> -
A23: Recommended Safe Weekly Loss Range | B23: 0.5 - 0.75 kg/week
A24: Implied Weeks at Safe Pace (0.6 kg/wk) | B24: =B12/0.6 -> 15.333333
A26: Current BMI | B26: =B9/((B3/100)^2) -> 28.885553
A27: Goal BMI | B27: =B6/((B3/100)^2) -> 25.15315
A30: How this updates:
A31: Add new rows to the 'Daily Log' sheet. Every figure on this sheet - average deficit, days/weeks/date to reach goal, BMI - recalculates automatically. Yellow cells are the only manual inputs (height, start date/weight, goal weight, kcal-per-kg constant).

Sheet Weekly Summary
A1: Week Start | B1: Week End | C1: Avg Calories Eaten | D1: Avg Calories Burned | E1: Avg Net Deficit | F1: Days Logged | G1: End-of-Week Weight (kg) | H1: Weight Change vs Prior Week (kg)
A2: 46181 | B2: 46187 | C2: =IFERROR(AVERAGEIFS('Daily Log'!$G$2:$G$80,'Daily Log'!$A$2:$A$80,">="&A2,'Daily Log'!$A$2:$A$80,"<="&B2,'Daily Log'!$M$2:$M$80,1),"") -> 1825.7143 | D2: =IFERROR(AVERAGEIFS('Daily Log'!$I$2:$I$80,'Daily Log'!$A$2:$A$80,">="&A2,'Daily Log'!$A$2:$A$80,"<="&B2,'Daily Log'!$M$2:$M$80,1),"") -> 1537 | E2: =IF(OR(C2="",D2=""),"",D2-C2) -> -288.71429 | F2: =COUNTIFS('Daily Log'!$A$2:$A$80,">="&A2,'Daily Log'!$A$2:$A$80,"<="&B2,'Daily Log'!$G$2:$G$80,"<>"&"""") -> 7 | G2: =IFERROR(INDEX('Daily Log'!$K$2:$K$80,MATCH(_xlfn.MAXIFS('Daily Log'!$A$2:$A$80,'Daily Log'!$A$2:$A$80,">="&A2,'Daily Log'!$A$2:$A$80,"<="&B2,'Daily Log'!$K$2:$K$80,"<>"),'Daily Log'!$A$2:$A$80,0)),"") -> 71.3
A3: 46188 | B3: 46194 | C3: =IFERROR(AVERAGEIFS('Daily Log'!$G$2:$G$80,'Daily Log'!$A$2:$A$80,">="&A3,'Daily Log'!$A$2:$A$80,"<="&B3,'Daily Log'!$M$2:$M$80,1),"") -> 1677.8571 | D3: =IFERROR(AVERAGEIFS('Daily Log'!$I$2:$I$80,'Daily Log'!$A$2:$A$80,">="&A3,'Daily Log'!$A$2:$A$80,"<="&B3,'Daily Log'!$M$2:$M$80,1),"") -> 1675 | E3: =IF(OR(C3="",D3=""),"",D3-C3) -> -2.8571429 | F3: =COUNTIFS('Daily Log'!$A$2:$A$80,">="&A3,'Daily Log'!$A$2:$A$80,"<="&B3,'Daily Log'!$G$2:$G$80,"<>"&"""") -> 7 | G3: =IFERROR(INDEX('Daily Log'!$K$2:$K$80,MATCH(_xlfn.MAXIFS('Daily Log'!$A$2:$A$80,'Daily Log'!$A$2:$A$80,">="&A3,'Daily Log'!$A$2:$A$80,"<="&B3,'Daily Log'!$K$2:$K$80,"<>"),'Daily Log'!$A$2:$A$80,0)),"") -> 70.9 | H3: =IF(OR(G3="",G2=""),"",G3-G2) -> -0.4
A4: 46195 | B4: 46201 | C4: =IFERROR(AVERAGEIFS('Daily Log'!$G$2:$G$80,'Daily Log'!$A$2:$A$80,">="&A4,'Daily Log'!$A$2:$A$80,"<="&B4,'Daily Log'!$M$2:$M$80,1),"") -> 1740 | D4: =IFERROR(AVERAGEIFS('Daily Log'!$I$2:$I$80,'Daily Log'!$A$2:$A$80,">="&A4,'Daily Log'!$A$2:$A$80,"<="&B4,'Daily Log'!$M$2:$M$80,1),"") -> 1704 | E4: =IF(OR(C4="",D4=""),"",D4-C4) -> -36 | F4: =COUNTIFS('Daily Log'!$A$2:$A$80,">="&A4,'Daily Log'!$A$2:$A$80,"<="&B4,'Daily Log'!$G$2:$G$80,"<>"&"""") -> 7 | G4: =IFERROR(INDEX('Daily Log'!$K$2:$K$80,MATCH(_xlfn.MAXIFS('Daily Log'!$A$2:$A$80,'Daily Log'!$A$2:$A$80,">="&A4,'Daily Log'!$A$2:$A$80,"<="&B4,'Daily Log'!$K$2:$K$80,"<>"),'Daily Log'!$A$2:$A$80,0)),"") -> 70.5 | H4: =IF(OR(G4="",G3=""),"",G4-G3) -> -0.4
A5: 46202 | B5: 46208 | C5: =IFERROR(AVERAGEIFS('Daily Log'!$G$2:$G$80,'Daily Log'!$A$2:$A$80,">="&A5,'Daily Log'!$A$2:$A$80,"<="&B5,'Daily Log'!$M$2:$M$80,1),"") -> 1826.4286 | D5: =IFERROR(AVERAGEIFS('Daily Log'!$I$2:$I$80,'Daily Log'!$A$2:$A$80,">="&A5,'Daily Log'!$A$2:$A$80,"<="&B5,'Daily Log'!$M$2:$M$80,1),"") -> 1701.5714 | E5: =IF(OR(C5="",D5=""),"",D5-C5) -> -124.85714 | F5: =COUNTIFS('Daily Log'!$A$2:$A$80,">="&A5,'Daily Log'!$A$2:$A$80,"<="&B5,'Daily Log'!$G$2:$G$80,"<>"&"""") -> 7 | G5: =IFERROR(INDEX('Daily Log'!$K$2:$K$80,MATCH(_xlfn.MAXIFS('Daily Log'!$A$2:$A$80,'Daily Log'!$A$2:$A$80,">="&A5,'Daily Log'!$A$2:$A$80,"<="&B5,'Daily Log'!$K$2:$K$80,"<>"),'Daily Log'!$A$2:$A$80,0)),"") -> 71.6 | H5: =IF(OR(G5="",G4=""),"",G5-G4) -> 1.1
A6: 46209 | B6: 46215 | C6: =IFERROR(AVERAGEIFS('Daily Log'!$G$2:$G$80,'Daily Log'!$A$2:$A$80,">="&A6,'Daily Log'!$A$2:$A$80,"<="&B6,'Daily Log'!$M$2:$M$80,1),"") -> 1720.7143 | D6: =IFERROR(AVERAGEIFS('Daily Log'!$I$2:$I$80,'Daily Log'!$A$2:$A$80,">="&A6,'Daily Log'!$A$2:$A$80,"<="&B6,'Daily Log'!$M$2:$M$80,1),"") -> 1673.4286 | E6: =IF(OR(C6="",D6=""),"",D6-C6) -> -47.285714 | F6: =COUNTIFS('Daily Log'!$A$2:$A$80,">="&A6,'Daily Log'!$A$2:$A$80,"<="&B6,'Daily Log'!$G$2:$G$80,"<>"&"""") -> 7 | G6: =IFERROR(INDEX('Daily Log'!$K$2:$K$80,MATCH(_xlfn.MAXIFS('Daily Log'!$A$2:$A$80,'Daily Log'!$A$2:$A$80,">="&A6,'Daily Log'!$A$2:$A$80,"<="&B6,'Daily Log'!$K$2:$K$80,"<>"),'Daily Log'!$A$2:$A$80,0)),"") -> 70.65 | H6: =IF(OR(G6="",G5=""),"",G6-G5) -> -0.95
A7: 46216 | B7: 46222 | C7: =IFERROR(AVERAGEIFS('Daily Log'!$G$2:$G$80,'Daily Log'!$A$2:$A$80,">="&A7,'Daily Log'!$A$2:$A$80,"<="&B7,'Daily Log'!$M$2:$M$80,1),"") -> 1803.5714 | D7: =IFERROR(AVERAGEIFS('Daily Log'!$I$2:$I$80,'Daily Log'!$A$2:$A$80,">="&A7,'Daily Log'!$A$2:$A$80,"<="&B7,'Daily Log'!$M$2:$M$80,1),"") -> 1641.1429 | E7: =IF(OR(C7="",D7=""),"",D7-C7) -> -162.42857 | F7: =COUNTIFS('Daily Log'!$A$2:$A$80,">="&A7,'Daily Log'!$A$2:$A$80,"<="&B7,'Daily Log'!$G$2:$G$80,"<>"&"""") -> 7 | G7: =IFERROR(INDEX('Daily Log'!$K$2:$K$80,MATCH(_xlfn.MAXIFS('Daily Log'!$A$2:$A$80,'Daily Log'!$A$2:$A$80,">="&A7,'Daily Log'!$A$2:$A$80,"<="&B7,'Daily Log'!$K$2:$K$80,"<>"),'Daily Log'!$A$2:$A$80,0)),"") -> 70.9 | H7: =IF(OR(G7="",G6=""),"",G7-G6) -> 0.25
A8: 46223 | B8: 46229 | C8: =IFERROR(AVERAGEIFS('Daily Log'!$G$2:$G$80,'Daily Log'!$A$2:$A$80,">="&A8,'Daily Log'!$A$2:$A$80,"<="&B8,'Daily Log'!$M$2:$M$80,1),"") -> 1611.4286 | D8: =IFERROR(AVERAGEIFS('Daily Log'!$I$2:$I$80,'Daily Log'!$A$2:$A$80,">="&A8,'Daily Log'!$A$2:$A$80,"<="&B8,'Daily Log'!$M$2:$M$80,1),"") -> 1744.4286 | E8: =IF(OR(C8="",D8=""),"",D8-C8) -> 133 | F8: =COUNTIFS('Daily Log'!$A$2:$A$80,">="&A8,'Daily Log'!$A$2:$A$80,"<="&B8,'Daily Log'!$G$2:$G$80,"<>"&"""") -> 7 | G8: =IFERROR(INDEX('Daily Log'!$K$2:$K$80,MATCH(_xlfn.MAXIFS('Daily Log'!$A$2:$A$80,'Daily Log'!$A$2:$A$80,">="&A8,'Daily Log'!$A$2:$A$80,"<="&B8,'Daily Log'!$K$2:$K$80,"<>"),'Daily Log'!$A$2:$A$80,0)),"") -> 70.4 | H8: =IF(OR(G8="",G7=""),"",G8-G7) -> -0.5
A9: 46230 | B9: 46236 | C9: =IFERROR(AVERAGEIFS('Daily Log'!$G$2:$G$80,'Daily Log'!$A$2:$A$80,">="&A9,'Daily Log'!$A$2:$A$80,"<="&B9,'Daily Log'!$M$2:$M$80,1),"") -> 1720 | D9: =IFERROR(AVERAGEIFS('Daily Log'!$I$2:$I$80,'Daily Log'!$A$2:$A$80,">="&A9,'Daily Log'!$A$2:$A$80,"<="&B9,'Daily Log'!$M$2:$M$80,1),"") -> 1950.8571 | E9: =IF(OR(C9="",D9=""),"",D9-C9) -> 230.85714 | F9: =COUNTIFS('Daily Log'!$A$2:$A$80,">="&A9,'Daily Log'!$A$2:$A$80,"<="&B9,'Daily Log'!$G$2:$G$80,"<>"&"""") -> 7 | G9: =IFERROR(INDEX('Daily Log'!$K$2:$K$80,MATCH(_xlfn.MAXIFS('Daily Log'!$A$2:$A$80,'Daily Log'!$A$2:$A$80,">="&A9,'Daily Log'!$A$2:$A$80,"<="&B9,'Daily Log'!$K$2:$K$80,"<>"),'Daily Log'!$A$2:$A$80,0)),"") -> 70.8 | H9: =IF(OR(G9="",G8=""),"",G9-G8) -> 0.4
A10: 46237 | B10: 46243 | C10: =IFERROR(AVERAGEIFS('Daily Log'!$G$2:$G$80,'Daily Log'!$A$2:$A$80,">="&A10,'Daily Log'!$A$2:$A$80,"<="&B10,'Daily Log'!$M$2:$M$80,1),"") -> 1687.5714 | D10: =IFERROR(AVERAGEIFS('Daily Log'!$I$2:$I$80,'Daily Log'!$A$2:$A$80,">="&A10,'Daily Log'!$A$2:$A$80,"<="&B10,'Daily Log'!$M$2:$M$80,1),"") -> 1936.8571 | E10: =IF(OR(C10="",D10=""),"",D10-C10) -> 249.28571 | F10: =COUNTIFS('Daily Log'!$A$2:$A$80,">="&A10,'Daily Log'!$A$2:$A$80,"<="&B10,'Daily Log'!$G$2:$G$80,"<>"&"""") -> 7 | G10: =IFERROR(INDEX('Daily Log'!$K$2:$K$80,MATCH(_xlfn.MAXIFS('Daily Log'!$A$2:$A$80,'Daily Log'!$A$2:$A$80,">="&A10,'Daily Log'!$A$2:$A$80,"<="&B10,'Daily Log'!$K$2:$K$80,"<>"),'Daily Log'!$A$2:$A$80,0)),"") -> 70.8 | H10: =IF(OR(G10="",G9=""),"",G10-G9) -> 0
A11: 46244 | B11: 46250 | C11: =IFERROR(AVERAGEIFS('Daily Log'!$G$2:$G$80,'Daily Log'!$A$2:$A$80,">="&A11,'Daily Log'!$A$2:$A$80,"<="&B11,'Daily Log'!$M$2:$M$80,1),"") -> 1847.1429 | D11: =IFERROR(AVERAGEIFS('Daily Log'!$I$2:$I$80,'Daily Log'!$A$2:$A$80,">="&A11,'Daily Log'!$A$2:$A$80,"<="&B11,'Daily Log'!$M$2:$M$80,1),"") -> 1802.4286 | E11: =IF(OR(C11="",D11=""),"",D11-C11) -> -44.714286 | F11: =COUNTIFS('Daily Log'!$A$2:$A$80,">="&A11,'Daily Log'!$A$2:$A$80,"<="&B11,'Daily Log'!$G$2:$G$80,"<>"&"""") -> 7 | G11: =IFERROR(INDEX('Daily Log'!$K$2:$K$80,MATCH(_xlfn.MAXIFS('Daily Log'!$A$2:$A$80,'Daily Log'!$A$2:$A$80,">="&A11,'Daily Log'!$A$2:$A$80,"<="&B11,'Daily Log'!$K$2:$K$80,"<>"),'Daily Log'!$A$2:$A$80,0)),"") -> 71 | H11: =IF(OR(G11="",G10=""),"",G11-G10) -> 0.2
A12: 46251 | B12: 46257 | C12: =IFERROR(AVERAGEIFS('Daily Log'!$G$2:$G$80,'Daily Log'!$A$2:$A$80,">="&A12,'Daily Log'!$A$2:$A$80,"<="&B12,'Daily Log'!$M$2:$M$80,1),"") -> 1654.2857 | D12: =IFERROR(AVERAGEIFS('Daily Log'!$I$2:$I$80,'Daily Log'!$A$2:$A$80,">="&A12,'Daily Log'!$A$2:$A$80,"<="&B12,'Daily Log'!$M$2:$M$80,1),"") -> 1607.7143 | E12: =IF(OR(C12="",D12=""),"",D12-C12) -> -46.571429 | F12: =COUNTIFS('Daily Log'!$A$2:$A$80,">="&A12,'Daily Log'!$A$2:$A$80,"<="&B12,'Daily Log'!$G$2:$G$80,"<>"&"""") -> 7 | G12: =IFERROR(INDEX('Daily Log'!$K$2:$K$80,MATCH(_xlfn.MAXIFS('Daily Log'!$A$2:$A$80,'Daily Log'!$A$2:$A$80,">="&A12,'Daily Log'!$A$2:$A$80,"<="&B12,'Daily Log'!$K$2:$K$80,"<>"),'Daily Log'!$A$2:$A$80,0)),"") -> 71.3 | H12: =IF(OR(G12="",G11=""),"",G12-G11) -> 0.3
A13: 46258 | B13: 46264 | C13: =IFERROR(AVERAGEIFS('Daily Log'!$G$2:$G$80,'Daily Log'!$A$2:$A$80,">="&A13,'Daily Log'!$A$2:$A$80,"<="&B13,'Daily Log'!$M$2:$M$80,1),"") -> 1900 | D13: =IFERROR(AVERAGEIFS('Daily Log'!$I$2:$I$80,'Daily Log'!$A$2:$A$80,">="&A13,'Daily Log'!$A$2:$A$80,"<="&B13,'Daily Log'!$M$2:$M$80,1),"") -> 1643 | E13: =IF(OR(C13="",D13=""),"",D13-C13) -> -257 | F13: =COUNTIFS('Daily Log'!$A$2:$A$80,">="&A13,'Daily Log'!$A$2:$A$80,"<="&B13,'Daily Log'!$G$2:$G$80,"<>"&"""") -> 2 | G13: =IFERROR(INDEX('Daily Log'!$K$2:$K$80,MATCH(_xlfn.MAXIFS('Daily Log'!$A$2:$A$80,'Daily Log'!$A$2:$A$80,">="&A13,'Daily Log'!$A$2:$A$80,"<="&B13,'Daily Log'!$K$2:$K$80,"<>"),'Daily Log'!$A$2:$A$80,0)),"") -> 71.2 | H13: =IF(OR(G13="",G12=""),"",G13-G12) -> -0.1

Sheet Monthly Summary
A1: Month | B1: Avg Calories Eaten | C1: Avg Calories Burned | D1: Avg Net Deficit | E1: Days Logged | F1: Start-of-Month Weight (kg) | G1: End-of-Month Weight (kg) | H1: Weight Change (kg)
A2: June 2026 | B2: =IFERROR(AVERAGEIFS('Daily Log'!$G$2:$G$80,'Daily Log'!$A$2:$A$80,">="&DATE(2026,6,1),'Daily Log'!$A$2:$A$80,"<="&DATE(2026,6,30),'Daily Log'!$M$2:$M$80,1),"") -> 1738.75 | C2: =IFERROR(AVERAGEIFS('Daily Log'!$I$2:$I$80,'Daily Log'!$A$2:$A$80,">="&DATE(2026,6,1),'Daily Log'!$A$2:$A$80,"<="&DATE(2026,6,30),'Daily Log'!$M$2:$M$80,1),"") -> 1642.65 | D2: =IF(OR(B2="",C2=""),"",C2-B2) -> -96.1 | E2: =COUNTIFS('Daily Log'!$A$2:$A$80,">="&DATE(2026,6,1),'Daily Log'!$A$2:$A$80,"<="&DATE(2026,6,30),'Daily Log'!$G$2:$G$80,"<>"&"""") -> 23 | F2: =IFERROR(INDEX('Daily Log'!$K$2:$K$80,MATCH(_xlfn.MINIFS('Daily Log'!$A$2:$A$80,'Daily Log'!$A$2:$A$80,">="&DATE(2026,6,1),'Daily Log'!$A$2:$A$80,"<="&DATE(2026,6,30),'Daily Log'!$K$2:$K$80,"<>"),'Daily Log'!$A$2:$A$80,0)),"") -> 71.3 | G2: =IFERROR(INDEX('Daily Log'!$K$2:$K$80,MATCH(_xlfn.MAXIFS('Daily Log'!$A$2:$A$80,'Daily Log'!$A$2:$A$80,">="&DATE(2026,6,1),'Daily Log'!$A$2:$A$80,"<="&DATE(2026,6,30),'Daily Log'!$K$2:$K$80,"<>"),'Daily Log'!$A$2:$A$80,0)),"") -> 71.6 | H2: =IF(OR(F2="",G2=""),"",G2-F2) -> 0.3
A3: July 2026 | B3: =IFERROR(AVERAGEIFS('Daily Log'!$G$2:$G$80,'Daily Log'!$A$2:$A$80,">="&DATE(2026,7,1),'Daily Log'!$A$2:$A$80,"<="&DATE(2026,7,31),'Daily Log'!$M$2:$M$80,1),"") -> 1749.5161 | C3: =IFERROR(AVERAGEIFS('Daily Log'!$I$2:$I$80,'Daily Log'!$A$2:$A$80,">="&DATE(2026,7,1),'Daily Log'!$A$2:$A$80,"<="&DATE(2026,7,31),'Daily Log'!$M$2:$M$80,1),"") -> 1704.8065 | D3: =IF(OR(B3="",C3=""),"",C3-B3) -> -44.709677 | E3: =COUNTIFS('Daily Log'!$A$2:$A$80,">="&DATE(2026,7,1),'Daily Log'!$A$2:$A$80,"<="&DATE(2026,7,31),'Daily Log'!$G$2:$G$80,"<>"&"""") -> 31 | F3: =IFERROR(INDEX('Daily Log'!$K$2:$K$80,MATCH(_xlfn.MINIFS('Daily Log'!$A$2:$A$80,'Daily Log'!$A$2:$A$80,">="&DATE(2026,7,1),'Daily Log'!$A$2:$A$80,"<="&DATE(2026,7,31),'Daily Log'!$K$2:$K$80,"<>"),'Daily Log'!$A$2:$A$80,0)),"") -> 70.65 | G3: =IFERROR(INDEX('Daily Log'!$K$2:$K$80,MATCH(_xlfn.MAXIFS('Daily Log'!$A$2:$A$80,'Daily Log'!$A$2:$A$80,">="&DATE(2026,7,1),'Daily Log'!$A$2:$A$80,"<="&DATE(2026,7,31),'Daily Log'!$K$2:$K$80,"<>"),'Daily Log'!$A$2:$A$80,0)),"") -> 70.8 | H3: =IF(OR(F3="",G3=""),"",G3-F3) -> 0.15
A4: August 2026 | B4: =IFERROR(AVERAGEIFS('Daily Log'!$G$2:$G$80,'Daily Log'!$A$2:$A$80,">="&DATE(2026,8,1),'Daily Log'!$A$2:$A$80,"<="&DATE(2026,8,31),'Daily Log'!$M$2:$M$80,1),"") -> 1728.0417 | C4: =IFERROR(AVERAGEIFS('Daily Log'!$I$2:$I$80,'Daily Log'!$A$2:$A$80,">="&DATE(2026,8,1),'Daily Log'!$A$2:$A$80,"<="&DATE(2026,8,31),'Daily Log'!$M$2:$M$80,1),"") -> 1818.75 | D4: =IF(OR(B4="",C4=""),"",C4-B4) -> 90.708333 | E4: =COUNTIFS('Daily Log'!$A$2:$A$80,">="&DATE(2026,8,1),'Daily Log'!$A$2:$A$80,"<="&DATE(2026,8,31),'Daily Log'!$G$2:$G$80,"<>"&"""") -> 25 | F4: =IFERROR(INDEX('Daily Log'!$K$2:$K$80,MATCH(_xlfn.MINIFS('Daily Log'!$A$2:$A$80,'Daily Log'!$A$2:$A$80,">="&DATE(2026,8,1),'Daily Log'!$A$2:$A$80,"<="&DATE(2026,8,31),'Daily Log'!$K$2:$K$80,"<>"),'Daily Log'!$A$2:$A$80,0)),"") -> 70.8 | G4: =IFERROR(INDEX('Daily Log'!$K$2:$K$80,MATCH(_xlfn.MAXIFS('Daily Log'!$A$2:$A$80,'Daily Log'!$A$2:$A$80,">="&DATE(2026,8,1),'Daily Log'!$A$2:$A$80,"<="&DATE(2026,8,31),'Daily Log'!$K$2:$K$80,"<>"),'Daily Log'!$A$2:$A$80,0)),"") -> 71.2 | H4: =IF(OR(F4="",G4=""),"",G4-F4) -> 0.4
